Workbook

Sheet Tasks
A1: Dino Hunt — implementation task tracker
A2: Greenfield build · Fusion + Nevermore · place 96665470525866 · plan: docs/06-project-plan.md
A3: Edit only the Status and Notes columns. Everything else is derived from the plan.
A5: ID | B5: Phase | C5: Area | D5: Task | E5: Acceptance criteria | F5: Depends on | G5: Est (d) | H5: Pri | I5: Status | J5: FR ref | K5: Notes
A6: DH-001 | B6: 0 | C6: Toolchain | D6: Install and pin Rokit toolchain | E6: rokit.toml pins rojo, wally, selene, stylua; `rokit install` succeeds | G6: 0.25 | H6: M | I6: Cut | K6: Void — no Rojo/Wally. Decided 2026-09-28.
A7: DH-002 | B7: 0 | C7: Toolchain | D7: Pin Fusion and Nevermore in wally.toml | E7: Exact versions pinned, not ranges. Fusion major recorded in docs (0.3 changed the API). | F7: DH-001 | G7: 0.5 | H7: M | I7: Cut | K7: Void — no Wally. Fusion installed from its GitHub .rbxm instead; Nevermore dropped.
A8: DH-003 | B8: 0 | C8: Toolchain | D8: Write default.project.json | E8: Maps src/shared, src/server, src/client, src/assets per plan section 3 | F8: DH-001 | G8: 0.25 | H8: M | I8: Cut | K8: Void — no Rojo.
A9: DH-004 | B9: 0 | C9: Toolchain | D9: Selene and StyLua config | E9: Both run clean on an empty project | F9: DH-001 | G9: 0.25 | H9: M | I9: Not started | K9: Can still run manually against exported source.
A10: DH-005 | B10: 0 | C10: Structure | D10: Create src skeleton | E10: shared/Config, shared/Net, shared/Types, shared/Util, server/Services, client/Controllers, client/UI | F10: DH-003 | G10: 0.25 | H10: M | I10: Done | K10: Built in-place: ReplicatedStorage.Shared{Config,Net,Types,Util}, Server.Services, Client{Controllers,UI}.
A11: DH-006 | B11: 0 | C11: Structure | D11: ServiceBag bootstrap | E11: init.server.luau builds the bag and starts services; init.client.luau mirrors it | F11: DH-005 | G11: 0.5 | H11: M | I11: Done | K11: ServiceBag + Bootstrap live. Server log: '0 service(s)', no errors.
A12: DH-007 | B12: 0 | C12: Toolchain | D12: Prove the Rojo round trip | E12: Edit a file, Rojo syncs, change visible in Dino Hunt place | F12: DH-006 | G12: 0.25 | H12: M | I12: Cut | K12: Void — no Rojo. MCP set_script_source is the authoring path.
A13: DH-008 | B13: 0 | C13: UI | D13: Reference Fusion component | E13: One trivial HUD element renders in-game from a file edit. Sets the pattern for every later component. | F13: DH-007 | G13: 0.5 | H13: M | I13: Done | K13: Client.Bootstrap renders the HUD; Computed followed Value 0->1. Fusion 0.3 confirmed.
A14: DH-009 | B14: 0 | C14: Process | D14: Commit the skeleton | E14: Pushed to master; wally.lock committed | F14: DH-008 | G14: 0.25 | H14: M | I14: Not started
A15: DH-010 | B15: 1 | C15: World | D15: Blockout: reactor core and defense ring | E15: Central structure with a visibly read defense ring on the floor | F15: DH-009 | G15: 0.5 | H15: M | I15: Not started | J15: FR-10
A16: DH-011 | B16: 1 | C16: World | D16: Blockout: approach lanes and spawn markers | E16: 2-3 lanes that read clearly from the reactor; spawn points marked | F16: DH-010 | G16: 0.5 | H16: M | I16: Not started
A17: DH-012 | B17: 1 | C17: World | D17: Blockout: sector volumes and gates | E17: Four bounded areas behind gate volumes | F17: DH-010 | G17: 0.5 | H17: M | I17: Not started | J17: FR-30
A18: DH-013 | B18: 1 | C18: World | D18: Export blockout to .rbxmx | E18: Committed under src/assets; replaceable without touching code | F18: DH-012 | G18: 0.25 | H18: M | I18: Not started
A19: DH-014 | B19: 1 | C19: Config | D19: Species table and derivation formulas | E19: One lp weight per species; baseHP/damage/rewards all derived. Comment the constants. | F19: DH-009 | G19: 0.5 | H19: M | I19: Not started | J19: FR-60
A20: DH-015 | B20: 1 | C20: Creature | D20: Grey-box rig: swarmer | E20: Part-built, distinct silhouette, flat colour, walk cycle only | F20: DH-009 | G20: 0.5 | H20: M | I20: Not started | J20: FR-60
A21: DH-016 | B21: 1 | C21: Creature | D21: CreatureService: spawn and pooling | E21: Pooled instances; no per-spawn instantiation spikes | F21: DH-014 | G21: 0.75 | H21: M | I21: Not started | J21: NFR-P5
A22: DH-017 | B22: 1 | C22: Creature | D22: Concurrency cap from day one | E22: min(perPlayer x live, MAX_ACTIVE); one server-wide cap | F22: DH-016 | G22: 0.25 | H22: M | I22: Not started | J22: NFR-P2
A23: DH-018 | B23: 1 | C23: Creature | D23: Pathing to the reactor | E23: Creature walks a lane and reaches the defense ring | F23: DH-016 | G23: 0.75 | H23: M | I23: Not started
A24: DH-019 | B24: 1 | C24: Combat | D24: CombatService: hitscan rifle | E24: Server-validated: fire rate, ammo, origin sanity | F24: DH-006 | G24: 1 | H24: M | I24: Not started | J24: NFR-S1
A25: DH-020 | B25: 1 | C25: Combat | D25: Damage, death and the one-shot invariant | E25: Wave-1 creature dies to exactly one starter shot | F25: DH-019 | G25: 0.5 | H25: M | I25: Not started | J25: FR-61
A26: DH-021 | B26: 2 | C26: Wave | D26: WaveService: 20 finite wave definitions | E26: Wave counter reaches 20; no wave 21 | F26: DH-020 | G26: 1 | H26: M | I26: Not started | J26: FR-01
A27: DH-022 | B27: 2 | C27: Wave | D27: Wave composition table in Config | E27: Per-wave species and counts; sums verified | F27: DH-021 | G27: 0.5 | H27: M | I27: Not started
A28: DH-023 | B28: 2 | C28: Wave | D28: Batched spawning from a reservoir | E28: Concurrency cap never exceeded mid-wave | F28: DH-022 | G28: 0.5 | H28: M | I28: Not started | J28: NFR-P2
A29: DH-024 | B29: 2 | C29: Wave | D29: Intermission (15s) | E29: Timer visible; buy actions available | F29: DH-021 | G29: 0.5 | H29: M | I29: Not started | J29: FR-05
A30: DH-025 | B30: 2 | C30: Creature | D30: Grey-box rig: flanker | E30: Medium, lean silhouette | F30: DH-015 | G30: 0.4 | H30: M | I30: Not started | J30: FR-60
A31: DH-026 | B31: 2 | C31: Creature | D31: Grey-box rig: armoured | E31: Wide, tall front plate | F31: DH-015 | G31: 0.4 | H31: M | I31: Not started | J31: FR-60
A32: DH-027 | B32: 2 | C32: Creature | D32: Grey-box rig: ranged | E32: Medium with a marked head; telegraphed spit | F32: DH-015 | G32: 0.6 | H32: M | I32: Not started | J32: FR-60
A33: DH-028 | B33: 2 | C33: Combat | D33: Directional armour | E33: Shots blocked within a cone of facing; land from the flank | F33: DH-026 | G33: 0.75 | H33: M | I33: Not started
A34: DH-029 | B34: 2 | C34: Wave | D34: Victory at wave 20 | E34: Victory screen; rewards granted once | F34: DH-021 | G34: 0.4 | H34: M | I34: Not started | J34: FR-02
A35: DH-030 | B35: 2 | C35: Wave | D35: Defeat state stub | E35: Placeholder until the reactor exists | F35: DH-021 | G35: 0.25 | H35: M | I35: Not started | J35: FR-03
A36: DH-031 | B36: 3 | C36: Objective | D36: Reactor instance and server-owned HP | E36: HP replicates; not client-writable | F36: DH-010 | G36: 0.5 | H36: M | I36: Not started | J36: FR-10
A37: DH-032 | B37: 3 | C37: Objective | D37: Reactor damage intake and ring targeting | E37: Creatures reaching the ring attack it; HP falls | F37: DH-031 | G37: 0.75 | H37: M | I37: Not started | J37: FR-11
A38: DH-033 | B38: 3 | C38: Objective | D38: Repair interaction | E38: Hold-interact; costs Credits; rate from Config | F38: DH-032 | G38: 0.5 | H38: M | I38: Not started | J38: FR-12
A39: DH-034 | B39: 3 | C39: Objective | D39: Defeat on reactor at 0 HP | E39: Defeat screen; checkpoint rewards retained | F39: DH-032 | G39: 0.4 | H39: M | I39: Not started | J39: FR-03
A40: DH-035 | B40: 3 | C40: Economy | D40: Amber drops, server-owned | E40: Amber never enters a backpack | F40: DH-031 | G40: 0.5 | H40: M | I40: Not started | J40: FR-13
A41: DH-036 | B41: 3 | C41: Economy | D41: Amber magnet flight and gauge | E41: 0.5-1.2s curve; value added exactly once; VFX culled on low-end | F41: DH-035 | G41: 0.75 | H41: M | I41: Not started | J41: FR-14
...

Sheet Phases
A1: Phase rollup
A2: Every figure here is a formula over the Tasks sheet. Nothing to edit.
A4: Phase | B4: Name | C4: Goal | D4: Tasks | E4: Done | F4: Est (d) | G4: Done (d) | H4: % complete | I4: Exit criteria
A5: 0 | B5: Toolchain | C5: Nothing else can start until this is done | D5: =COUNTIFS(Tasks!$B$6:$B$79,$A5) -> 11 | E5: =COUNTIFS(Tasks!$B$6:$B$79,$A5,Tasks!$I$6:$I$79,"Done") -> 3 | F5: =SUMIFS(Tasks!$G$6:$G$79,Tasks!$B$6:$B$79,$A5) -> 3.75 | G5: =SUMIFS(Tasks!$G$6:$G$79,Tasks!$B$6:$B$79,$A5,Tasks!$I$6:$I$79,"Done") -> 1.25 | H5: =IFERROR(G5/F5,0) -> 0.33333333 | I5: A trivial Fusion HUD element renders in-game from a file edit
A6: 1 | B6: Blockout and creature stub | C6: Prove one creature, one gun, one lane | D6: =COUNTIFS(Tasks!$B$6:$B$79,$A6) -> 11 | E6: =COUNTIFS(Tasks!$B$6:$B$79,$A6,Tasks!$I$6:$I$79,"Done") -> 0 | F6: =SUMIFS(Tasks!$G$6:$G$79,Tasks!$B$6:$B$79,$A6) -> 6 | G6: =SUMIFS(Tasks!$G$6:$G$79,Tasks!$B$6:$B$79,$A6,Tasks!$I$6:$I$79,"Done") -> 0 | H6: =IFERROR(G6/F6,0) -> 0 | I6: A creature walks a lane and dies to one rifle shot
A7: 2 | B7: The wave loop | C7: Twenty finite waves with four creature roles | D7: =COUNTIFS(Tasks!$B$6:$B$79,$A7) -> 10 | E7: =COUNTIFS(Tasks!$B$6:$B$79,$A7,Tasks!$I$6:$I$79,"Done") -> 0 | F7: =SUMIFS(Tasks!$G$6:$G$79,Tasks!$B$6:$B$79,$A7) -> 5.3 | G7: =SUMIFS(Tasks!$G$6:$G$79,Tasks!$B$6:$B$79,$A7,Tasks!$I$6:$I$79,"Done") -> 0 | H7: =IFERROR(G7/F7,0) -> 0 | I7: A full 20-wave run completes
A8: 3 | B8: The spine | C8: Something to defend; the run can be won or lost | D8: =COUNTIFS(Tasks!$B$6:$B$79,$A8) -> 11 | E8: =COUNTIFS(Tasks!$B$6:$B$79,$A8,Tasks!$I$6:$I$79,"Done") -> 0 | F8: =SUMIFS(Tasks!$G$6:$G$79,Tasks!$B$6:$B$79,$A8) -> 5.7 | G8: =SUMIFS(Tasks!$G$6:$G$79,Tasks!$B$6:$B$79,$A8,Tasks!$I$6:$I$79,"Done") -> 0 | H8: =IFERROR(G8/F8,0) -> 0 | I8: A run can be won and lost; the reactor is the objective
A9: 4 | B9: Boss and exploration | C9: The loop the game is actually about | D9: =COUNTIFS(Tasks!$B$6:$B$79,$A9) -> 11 | E9: =COUNTIFS(Tasks!$B$6:$B$79,$A9,Tasks!$I$6:$I$79,"Done") -> 0 | F9: =SUMIFS(Tasks!$G$6:$G$79,Tasks!$B$6:$B$79,$A9) -> 6.55 | G9: =SUMIFS(Tasks!$G$6:$G$79,Tasks!$B$6:$B$79,$A9,Tasks!$I$6:$I$79,"Done") -> 0 | H9: =IFERROR(G9/F9,0) -> 0 | I9: Wave 4 boss to sector opens to exploration to safe return
A10: 5 | B10: The collection loop | C10: The reason players come back | D10: =COUNTIFS(Tasks!$B$6:$B$79,$A10) -> 10 | E10: =COUNTIFS(Tasks!$B$6:$B$79,$A10,Tasks!$I$6:$I$79,"Done") -> 0 | F10: =SUMIFS(Tasks!$G$6:$G$79,Tasks!$B$6:$B$79,$A10) -> 6.3 | G10: =SUMIFS(Tasks!$G$6:$G$79,Tasks!$B$6:$B$79,$A10,Tasks!$I$6:$I$79,"Done") -> 0 | H10: =IFERROR(G10/F10,0) -> 0 | I10: An egg survives a disconnect and hatches into exactly one pet
A11: 6 | B11: Players and hardening | C11: Make it hold up | D11: =COUNTIFS(Tasks!$B$6:$B$79,$A11) -> 10 | E11: =COUNTIFS(Tasks!$B$6:$B$79,$A11,Tasks!$I$6:$I$79,"Done") -> 0 | F11: =SUMIFS(Tasks!$G$6:$G$79,Tasks!$B$6:$B$79,$A11) -> 6.3 | G11: =SUMIFS(Tasks!$G$6:$G$79,Tasks!$B$6:$B$79,$A11,Tasks!$I$6:$I$79,"Done") -> 0 | H11: =IFERROR(G11/F11,0) -> 0 | I11: MVP slice exit criteria met
B12: TOTAL | D12: =SUM(D5:D11) -> 74 | E12: =SUM(E5:E11) -> 3 | F12: =SUM(F5:F11) -> 39.9 | G12: =SUM(G5:G11) -> 1.25 | H12: =IFERROR(G12/F12,0) -> 0.031328321
B14: Estimates assume one developer working with Claude Code. Phase 6's buffer is reserved — do not plan work into it.

Sheet Legend
A1: How to use this tracker
A4: Editing | B4: Change only the Status and Notes columns on the Tasks sheet. Everything else mirrors docs/06-project-plan.md; if the plan changes, the tracker is regenerated from it.
A6: Status values
A7: Not started | B7: Default. No work begun.
A8: In progress | B8: Actively being worked.
A9: Blocked | B9: Cannot proceed. Say why in Notes — and if it is a real decision, raise it in docs/03-open-decisions.md.
A10: Done | B10: Acceptance criteria met in a Studio play test, verified solo and with 2+ players, no new console errors.
A11: Cut | B11: Deliberately dropped. Say why in Notes.
A13: Priority
A14: M | B14: Must have for the MVP slice.
A15: S | B15: Should have. Cut first if a phase overruns.
A16: C | B16: Could have.
A18: Columns
A19: Depends on | B19: The task ID that must be Done first. Blank means it can start once its phase does.
A20: Est (d) | B20: Developer-days. Fractions are deliberate — most tasks are hours, not days.
A21: FR ref | B21: The functional or non-functional requirement in docs/archive/05-sdlc-plan.md. Those 64 requirements survived the greenfield restart unchanged.
A23: Definition of Done | B23: Acceptance criteria met · verified solo AND multiplayer · no new console errors across a full wave · server-authoritative · numbers live in src/shared/Config with a derivation comment · committed and pushed.
A25: Invariants | B25: Never break these: wave-1 creature dies to exactly one starter shot · every creature is slower than the player · nothing one-shots a full-health player · one server-wide concurrency cap · the client never reports a hit.
